User: Please make a plot of random_file_1.csv
Assistant(Aria): I have created a plot from the data in **random_file_1.csv**. You can view and download the plot using the following link: [View Plot](http://127.0.0.1:9527/public/apps/data-store/get?id=71665a12-e490-45b8-96d0-14281192b5bd).
Remaining quota: inf

Chat history saved to chatlogs-session-hhkev03p0.json
INFO:bioimageio-chatbot:User: {'id': 'google-oauth2|104255278140940970953', 'roles': [], 'is_anonymous': False, 'email': 'hugo.dettner@scilifelab.se', 'parent': None, 'scopes': ['openid', 'profile', 'email', 'offline_access'], 'expires_at': 1729929580.0}, Message: Please analyze the four files

Generating AriaDataAnalyzer (start): 
{"explore_request":"Perform a comprehensive analysis of the data in each file.","data_files":["http://127.0.0.1:9527/public/apps/data-store/get?id=4fb35412-3aad-4eab-bede-1834418ba1a2","http://127.0.0.1:9527/public/apps/data-store/get?id=3b23b909-4623-4830-b912-f62363098978","http://127.0.0.1:9527/public/apps/data-store/get?id=726764f1-d3ef-42b3-9d4c-fbf3fb11c170","http://127.0.0.1:9527/public/apps/data-store/get?id=ec1057a9-3045-43f5-943a-eee10186c8a2"],"project_name":"comprehensive_analysis","thoughts":{"reasoning":"Analyzing all files to provide a detailed overview and insights."}}
Generating AriaDataAnalyzer (finished): {"explore_request":"Perform a comprehensive analysis of the data in each file.","data_files":["http://127.0.0.1:9527/public/apps/data-store/get?id=4fb35412-3aad-4eab-bede-1834418ba1a2","http://127.0.0.1:9527/public/apps/data-store/get?id=3b23b909-4623-4830-b912-f62363098978","http://127.0.0.1:9527/public/apps/data-store/get?id=726764f1-d3ef-42b3-9d4c-fbf3fb11c170","http://127.0.0.1:9527/public/apps/data-store/get?id=ec1057a9-3045-43f5-943a-eee10186c8a2"],"project_name":"comprehensive_analysis","thoughts":{"reasoning":"Analyzing all files to provide a detailed overview and insights."}}
2024-10-25 10:14:58.060 | INFO     | schema_agents.provider.openai_api:update_cost:101 - Total running cost: $0.016 | Max budget: $10.000 | Current cost: $0.007, prompt_tokens=1808, completion_tokens=215
ERROR:pandasai.helpers.logger:Failed with error: Traceback (most recent call last):
  File "/Users/hugokallander/virtualenvs/aa4/lib/python3.10/site-packages/pandasai/pipelines/chat/code_execution.py", line 85, in execute
    result = self.execute_code(code_to_run, code_context)
  File "/Users/hugokallander/virtualenvs/aa4/lib/python3.10/site-packages/pandasai/pipelines/chat/code_execution.py", line 171, in execute_code
    exec(code, environment)
  File "<string>", line 4, in <module>
AttributeError: 'NoneType' object has no attribute 'mean'

WARNING:pandasai.helpers.logger:Failed to execute code retrying with a correction framework [retry number: 1]
Analysis for File 1:
Mean: {'File1_Col_1': 58.7, 'File1_Col_2': 50.9, 'File1_Col_3': 44.9, 'File1_Col_4': 55.1, 'File1_Col_5': 54.3}
Median: {'File1_Col_1': 61.5, 'File1_Col_2': 57.0, 'File1_Col_3': 49.5, 'File1_Col_4': 51.0, 'File1_Col_5': 57.0}
Std_dev: {'File1_Col_1': 25.289655329139357, 'File1_Col_2': 27.38795355626265, 'File1_Col_3': 23.216134236536643, 'File1_Col_4': 26.90084674421152, 'File1_Col_5': 28.54645336990219}
Min: {'File1_Col_1': 14, 'File1_Col_2': 15, 'File1_Col_3': 1, 'File1_Col_4': 9, 'File1_Col_5': 1}
Max: {'File1_Col_1': 97, 'File1_Col_2': 88, 'File1_Col_3': 83, 'File1_Col_4': 92, 'File1_Col_5': 94}
ERROR:pandasai.helpers.logger:Failed with error: Traceback (most recent call last):
  File "/Users/hugokallander/virtualenvs/aa4/lib/python3.10/site-packages/pandasai/pipelines/chat/code_execution.py", line 85, in execute
    result = self.execute_code(code_to_run, code_context)
  File "/Users/hugokallander/virtualenvs/aa4/lib/python3.10/site-packages/pandasai/pipelines/chat/code_execution.py", line 175, in execute_code
    raise NoResultFoundError("No result returned")
pandasai.exceptions.NoResultFoundError: No result returned

WARNING:pandasai.helpers.logger:Failed to execute code retrying with a correction framework [retry number: 2]
Analysis for File 1:
Mean: {'File1_Col_1': 58.7, 'File1_Col_2': 50.9, 'File1_Col_3': 44.9, 'File1_Col_4': 55.1, 'File1_Col_5': 54.3}
Median: {'File1_Col_1': 61.5, 'File1_Col_2': 57.0, 'File1_Col_3': 49.5, 'File1_Col_4': 51.0, 'File1_Col_5': 57.0}
Std_dev: {'File1_Col_1': 25.289655329139357, 'File1_Col_2': 27.38795355626265, 'File1_Col_3': 23.216134236536643, 'File1_Col_4': 26.90084674421152, 'File1_Col_5': 28.54645336990219}
Min: {'File1_Col_1': 14, 'File1_Col_2': 15, 'File1_Col_3': 1, 'File1_Col_4': 9, 'File1_Col_5': 1}
Max: {'File1_Col_1': 97, 'File1_Col_2': 88, 'File1_Col_3': 83, 'File1_Col_4': 92, 'File1_Col_5': 94}
ERROR:pandasai.helpers.logger:Failed with error: Traceback (most recent call last):
  File "/Users/hugokallander/virtualenvs/aa4/lib/python3.10/site-packages/pandasai/pipelines/chat/code_execution.py", line 85, in execute
    result = self.execute_code(code_to_run, code_context)
  File "/Users/hugokallander/virtualenvs/aa4/lib/python3.10/site-packages/pandasai/pipelines/chat/code_execution.py", line 175, in execute_code
    raise NoResultFoundError("No result returned")
pandasai.exceptions.NoResultFoundError: No result returned

WARNING:pandasai.helpers.logger:Failed to execute code retrying with a correction framework [retry number: 3]
Analysis for File 1:
Mean: {'File1_Col_1': 58.7, 'File1_Col_2': 50.9, 'File1_Col_3': 44.9, 'File1_Col_4': 55.1, 'File1_Col_5': 54.3}
Median: {'File1_Col_1': 61.5, 'File1_Col_2': 57.0, 'File1_Col_3': 49.5, 'File1_Col_4': 51.0, 'File1_Col_5': 57.0}
Std_dev: {'File1_Col_1': 25.289655329139357, 'File1_Col_2': 27.38795355626265, 'File1_Col_3': 23.216134236536643, 'File1_Col_4': 26.90084674421152, 'File1_Col_5': 28.54645336990219}
Min: {'File1_Col_1': 14, 'File1_Col_2': 15, 'File1_Col_3': 1, 'File1_Col_4': 9, 'File1_Col_5': 1}
Max: {'File1_Col_1': 97, 'File1_Col_2': 88, 'File1_Col_3': 83, 'File1_Col_4': 92, 'File1_Col_5': 94}
ERROR:pandasai.helpers.logger:Failed with error: Traceback (most recent call last):
  File "/Users/hugokallander/virtualenvs/aa4/lib/python3.10/site-packages/pandasai/pipelines/chat/code_execution.py", line 85, in execute
    result = self.execute_code(code_to_run, code_context)
  File "/Users/hugokallander/virtualenvs/aa4/lib/python3.10/site-packages/pandasai/pipelines/chat/code_execution.py", line 175, in execute_code
    raise NoResultFoundError("No result returned")
pandasai.exceptions.NoResultFoundError: No result returned

ERROR:pandasai.helpers.logger:Pipeline failed on step 6: No result returned
Traceback (most recent call last):
  File "/Users/hugokallander/virtualenvs/aa4/lib/python3.10/site-packages/pandasai/pipelines/chat/generate_chat_pipeline.py", line 335, in run
    ).run(input)
  File "/Users/hugokallander/virtualenvs/aa4/lib/python3.10/site-packages/pandasai/pipelines/pipeline.py", line 137, in run
    raise e
  File "/Users/hugokallander/virtualenvs/aa4/lib/python3.10/site-packages/pandasai/pipelines/pipeline.py", line 101, in run
    step_output = logic.execute(
  File "/Users/hugokallander/virtualenvs/aa4/lib/python3.10/site-packages/pandasai/pipelines/chat/code_execution.py", line 113, in execute
    raise e
  File "/Users/hugokallander/virtualenvs/aa4/lib/python3.10/site-packages/pandasai/pipelines/chat/code_execution.py", line 85, in execute
    result = self.execute_code(code_to_run, code_context)
  File "/Users/hugokallander/virtualenvs/aa4/lib/python3.10/site-packages/pandasai/pipelines/chat/code_execution.py", line 175, in execute_code
    raise NoResultFoundError("No result returned")
pandasai.exceptions.NoResultFoundError: No result returned

Generating CompleteUserQuery (start): 
{"response":"I attempted to analyze the four files, but unfortunately, there was an error in processing the data. It seems that no result was returned from the analysis attempt. This could be due to a variety of reasons, such as issues with the file format or data content.\n\nTo proceed, I recommend checking the files for any inconsistencies or errors in the data format. If the files are large, consider analyzing them in smaller parts or ensuring they are in a compatible format (e.g., CSV, Excel).\n\nIf you need further assistance, please let me know how you'd like to proceed, or if there are specific aspects of the data you want to focus on, I can try a different approach."}
Generating CompleteUserQuery (finished): {"response":"I attempted to analyze the four files, but unfortunately, there was an error in processing the data. It seems that no result was returned from the analysis attempt. This could be due to a variety of reasons, such as issues with the file format or data content.\n\nTo proceed, I recommend checking the files for any inconsistencies or errors in the data format. If the files are large, consider analyzing them in smaller parts or ensuring they are in a compatible format (e.g., CSV, Excel).\n\nIf you need further assistance, please let me know how you'd like to proceed, or if there are specific aspects of the data you want to focus on, I can try a different approach."}
2024-10-25 10:15:55.221 | INFO     | schema_agents.provider.openai_api:update_cost:101 - Total running cost: $0.023 | Max budget: $10.000 | Current cost: $0.007, prompt_tokens=2387, completion_tokens=149

User: Please analyze the four files
Assistant(Aria): I attempted to analyze the four files, but unfortunately, there was an error in processing the data. It seems that no result was returned from the analysis attempt. This could be due to a variety of reasons, such as issues with the file format or data content.

To proceed, I recommend checking the files for any inconsistencies or errors in the data format. If the files are large, consider analyzing them in smaller parts or ensuring they are in a compatible format (e.g., CSV, Excel).

If you need further assistance, please let me know how you'd like to proceed, or if there are specific aspects of the data you want to focus on, I can try a different approach.
Remaining quota: inf

Chat history saved to chatlogs-session-hhkev03p0.json